<robot name="example_robot">
	<link name="link0">
		<visual>
			<material name="blue">
				<color rgba="0 0 .8 1"/>
			</material>
			<geometry>
				<origin xyz="0 0 0" rpy="0 0 0"/>
				<cylinder length="0.6" radius="0.1"/>
			</geometry>
		</visual>
	</link>
	<link name="link1">
		<visual>
			<origin xyz="0 0 0.25" rpy="0 0 0"/>
			<material name="red"/>
			<geometry>
				<cylinder length="0.5" radius="0.05"/>
			</geometry>
		</visual>
	</link>
	<joint name="q1" type="revolute">
		<origin xyz="0 0 15.19" rpy="0 0 0"/>
		<parent link="link0"/>
		<child link="link1"/>
		<axis xyz="0 0 1"/>
        <limit effort="150.0" lower="-1.0" upper="1.0" velocity="3.15"/>
	</joint>
	<link name="link2">
		<visual>
			<origin xyz="0 0 0.25" rpy="0 0 0"/>
			<material name="red"/>
			<geometry>
				<cylinder length="0.5" radius="0.05"/>
			</geometry>
		</visual>
	</link>
	<joint name="q2" type="revolute">
		<origin xyz="0 0 0" rpy="1.5707963267948966 0 0"/>
		<parent link="link1"/>
		<child link="link2"/>
		<axis xyz="0 0 1"/>
        <limit effort="150.0" lower="-1.0" upper="1.0" velocity="3.15"/>
	</joint>
	<link name="link3">
		<visual>
			<origin xyz="0 0 0.25" rpy="0 0 0"/>
			<material name="red"/>
			<geometry>
				<cylinder length="0.5" radius="0.05"/>
			</geometry>
		</visual>
	</link>
	<joint name="q3" type="revolute">
		<origin xyz="-24.35 0 0" rpy="0 0 0"/>
		<parent link="link2"/>
		<child link="link3"/>
		<axis xyz="0 0 1"/>
        <limit effort="150.0" lower="-1.0" upper="1.0" velocity="3.15"/>
	</joint>
	<link name="link4">
		<visual>
			<origin xyz="0 0 0.25" rpy="0 0 0"/>
			<material name="red"/>
			<geometry>
				<cylinder length="0.5" radius="0.05"/>
			</geometry>
		</visual>
	</link>
	<joint name="q4" type="revolute">
		<origin xyz="-21.32 0 13.1" rpy="0 0 0"/>
		<parent link="link3"/>
		<child link="link4"/>
		<axis xyz="0 0 1"/>
        <limit effort="150.0" lower="-1.0" upper="1.0" velocity="3.15"/>
	</joint>
	<link name="link5">
		<visual>
			<origin xyz="0 0 0.25" rpy="0 0 0"/>
			<material name="red"/>
			<geometry>
				<cylinder length="0.5" radius="0.05"/>
			</geometry>
		</visual>
	</link>
	<joint name="q5" type="revolute">
		<origin xyz="0 -8.53 5.223118598363461e-16" rpy="1.5707963267948966 0 0"/>
		<parent link="link4"/>
		<child link="link5"/>
		<axis xyz="0 0 1"/>
        <limit effort="150.0" lower="-1.0" upper="1.0" velocity="3.15"/>
	</joint>
	<link name="link6">
		<visual>
			<origin xyz="0 0 0.25" rpy="0 0 0"/>
			<material name="red"/>
			<geometry>
				<cylinder length="0.5" radius="0.05"/>
			</geometry>
		</visual>
	</link>
	<joint name="q6" type="revolute">
		<origin xyz="0 9.21 5.639498510073562e-16" rpy="-1.5707963267948966 0 0"/>
		<parent link="link5"/>
		<child link="link6"/>
		<axis xyz="0 0 1"/>
        <limit effort="150.0" lower="-1.0" upper="1.0" velocity="3.15"/>
	</joint>
</robot>